Traceback (most recent call last):
  File "C:\Users\Vishal\AppData\Local\Programs\Python\Python312\Lib\site-packages\jupyter_cache\executors\utils.py", line 58, in single_nb_execution
    executenb(
  File "C:\Users\Vishal\AppData\Local\Programs\Python\Python312\Lib\site-packages\nbclient\client.py", line 1305, in execute
    return NotebookClient(nb=nb, resources=resources, km=km, **kwargs).execute()
           ^^^^^^^^^^^^^^^^^^^^^^^^^^^^^^^^^^^^^^^^^^^^^^^^^^^^^^^^^^^^^^^^^^^^^
  File "C:\Users\Vishal\AppData\Roaming\Python\Python312\site-packages\jupyter_core\utils\__init__.py", line 173, in wrapped
    return loop.run_until_complete(inner)
           ^^^^^^^^^^^^^^^^^^^^^^^^^^^^^^
  File "C:\Users\Vishal\AppData\Local\Programs\Python\Python312\Lib\asyncio\base_events.py", line 664, in run_until_complete
    return future.result()
           ^^^^^^^^^^^^^^^
  File "C:\Users\Vishal\AppData\Local\Programs\Python\Python312\Lib\site-packages\nbclient\client.py", line 705, in async_execute
    await self.async_execute_cell(
  File "C:\Users\Vishal\AppData\Local\Programs\Python\Python312\Lib\site-packages\nbclient\client.py", line 1058, in async_execute_cell
    await self._check_raise_for_error(cell, cell_index, exec_reply)
  File "C:\Users\Vishal\AppData\Local\Programs\Python\Python312\Lib\site-packages\nbclient\client.py", line 914, in _check_raise_for_error
    raise CellExecutionError.from_cell_and_msg(cell, exec_reply_content)
nbclient.exceptions.CellExecutionError: An error occurred while executing the following cell:
------------------
scaler = StandardScaler()

x_vals = np.array(usgs_grouped_counts["count"]).reshape(-1,1)
scaled_counts_arr = scaler.fit_transform(x_vals)

x_vals = np.array(usgs_grouped_max["mag"]).reshape(-1,1)
scaled_max_arr = scaler.fit_transform(x_vals)
------------------


[1;31m---------------------------------------------------------------------------[0m
[1;31mNameError[0m                                 Traceback (most recent call last)
Cell [1;32mIn[8], line 1[0m
[1;32m----> 1[0m scaler [38;5;241m=[39m [43mStandardScaler[49m()
[0;32m      3[0m x_vals [38;5;241m=[39m np[38;5;241m.[39marray(usgs_grouped_counts[[38;5;124m"[39m[38;5;124mcount[39m[38;5;124m"[39m])[38;5;241m.[39mreshape([38;5;241m-[39m[38;5;241m1[39m,[38;5;241m1[39m)
[0;32m      4[0m scaled_counts_arr [38;5;241m=[39m scaler[38;5;241m.[39mfit_transform(x_vals)

[1;31mNameError[0m: name 'StandardScaler' is not defined

